wandb: ERROR Error while calling W&B API: could not find agent wncuoh6i during agentHeartbeat (<Response [404]>)
Exception in thread Thread-22:
Traceback (most recent call last):
  File "C:\Users\Samsung\anaconda3\lib\site-packages\wandb\sdk\lib\retry.py", line 113, in __call__
    result = self._call_fn(*args, **kwargs)
  File "C:\Users\Samsung\anaconda3\lib\site-packages\wandb\sdk\internal\internal_api.py", line 213, in execute
    return self.client.execute(*args, **kwargs)  # type: ignore
  File "C:\Users\Samsung\anaconda3\lib\site-packages\wandb\vendor\gql-0.2.0\wandb_gql\client.py", line 52, in execute
    result = self._get_result(document, *args, **kwargs)
  File "C:\Users\Samsung\anaconda3\lib\site-packages\wandb\vendor\gql-0.2.0\wandb_gql\client.py", line 60, in _get_result
    return self.transport.execute(document, *args, **kwargs)
  File "C:\Users\Samsung\anaconda3\lib\site-packages\wandb\vendor\gql-0.2.0\wandb_gql\transport\requests.py", line 39, in execute
    request.raise_for_status()
  File "C:\Users\Samsung\anaconda3\lib\site-packages\requests\models.py", line 1021, in raise_for_status
    raise HTTPError(http_error_msg, response=self)
requests.exceptions.HTTPError: 404 Client Error: Not Found for url: https://api.wandb.ai/graphql
During handling of the above exception, another exception occurred:
Traceback (most recent call last):
  File "C:\Users\Samsung\anaconda3\lib\site-packages\wandb\sdk\internal\internal_api.py", line 2018, in agent_heartbeat
    response = self.gql(
  File "C:\Users\Samsung\anaconda3\lib\site-packages\wandb\sdk\lib\retry.py", line 129, in __call__
    retry_timedelta_triggered = check_retry_fn(e)
  File "C:\Users\Samsung\anaconda3\lib\site-packages\wandb\util.py", line 975, in no_retry_auth
    raise CommError(f"Permission denied to access {wandb.run.path}")
wandb.errors.CommError: Permission denied to access embarca-ai/TEDARegressor/11csfl7z
During handling of the above exception, another exception occurred:
Traceback (most recent call last):
  File "C:\Users\Samsung\anaconda3\lib\threading.py", line 932, in _bootstrap_inner
    self.run()
  File "C:\Users\Samsung\anaconda3\lib\threading.py", line 870, in run
    self._target(*self._args, **self._kwargs)
  File "C:\Users\Samsung\anaconda3\lib\site-packages\wandb\agents\pyagent.py", line 166, in _heartbeat
    commands = self._api.agent_heartbeat(self._agent_id, {}, run_status)
  File "C:\Users\Samsung\anaconda3\lib\site-packages\wandb\apis\internal.py", line 126, in agent_heartbeat
    return self.api.agent_heartbeat(*args, **kwargs)
  File "C:\Users\Samsung\anaconda3\lib\site-packages\wandb\sdk\internal\internal_api.py", line 2029, in agent_heartbeat
    message = ast.literal_eval(e.args[0])["message"]
  File "C:\Users\Samsung\anaconda3\lib\ast.py", line 59, in literal_eval
    node_or_string = parse(node_or_string, mode='eval')
  File "C:\Users\Samsung\anaconda3\lib\ast.py", line 47, in parse
    return compile(source, filename, mode, flags,
  File "<unknown>", line 1
    Permission denied to access embarca-ai/TEDARegressor/11csfl7z
               ^
